<?xml version="1.0" encoding="utf-8"?>
<mujoco model="SpiRob_2T">
  <compiler angle="degree" coordinate="local"/>
  <option gravity="0 0 -9.81" timestep="0.002"/>
  <default>
    <joint armature="0.01" damping="0.2" limited="true" range="-45 45"/>
    <geom density="900" friction="0.8 0.1 0.1" margin="0.002" condim="3"/>
  </default>
  <asset>
    <!-- визуальная сетка звена; если файла нет, можно удалить этот mesh -->
    <mesh name="hex_link" file="hex_base.obj"/>
  </asset>
  <worldbody>
    <body name="ground" pos="0 0 0">
      <geom name="floor" type="plane" size="2 2 0.02" rgba="0.9 0.9 0.9 1"/>
    </body>
    <body name="base" pos="0 0 0.03">
      <geom type="cylinder" size="0.015 0.01" rgba="0.7 0.7 0.7 1"/>
      <body name="link_0" pos="0.01875 0 0">
        <joint name="joint_0" type="hinge" axis="0 1 0"/>
        <geom type="capsule" fromto="-0.00937 0 0 0.00937 0 0" size="0.02000" rgba="0.8 0.8 1 1"/>
        <geom type="mesh" mesh="hex_link" rgba="0.8 0.8 0.9 0.3" scale="0.01875 0.04000 0.04000"/>
        <site name="s_left_0"  pos="0 0.02000 0" size="0.002" rgba="0 0 1 1"/>
        <site name="s_right_0" pos="0 -0.02000 0" size="0.002" rgba="1 0 0 1"/>
        <body name="link_1" pos="0.01875 0 0">
          <joint name="joint_1" type="hinge" axis="0 1 0"/>
          <geom type="capsule" fromto="-0.00937 0 0 0.00937 0 0" size="0.01939" rgba="0.8 0.8 1 1"/>
          <geom type="mesh" mesh="hex_link" rgba="0.8 0.8 0.9 0.3" scale="0.01875 0.03878 0.03878"/>
          <site name="s_left_1"  pos="0 0.01939 0" size="0.002" rgba="0 0 1 1"/>
          <site name="s_right_1" pos="0 -0.01939 0" size="0.002" rgba="1 0 0 1"/>
          <body name="link_2" pos="0.01875 0 0">
            <joint name="joint_2" type="hinge" axis="0 1 0"/>
            <geom type="capsule" fromto="-0.00937 0 0 0.00937 0 0" size="0.01878" rgba="0.8 0.8 1 1"/>
            <geom type="mesh" mesh="hex_link" rgba="0.8 0.8 0.9 0.3" scale="0.01875 0.03757 0.03757"/>
            <site name="s_left_2"  pos="0 0.01878 0" size="0.002" rgba="0 0 1 1"/>
            <site name="s_right_2" pos="0 -0.01878 0" size="0.002" rgba="1 0 0 1"/>
            <body name="link_3" pos="0.01875 0 0">
              <joint name="joint_3" type="hinge" axis="0 1 0"/>
              <geom type="capsule" fromto="-0.00937 0 0 0.00937 0 0" size="0.01817" rgba="0.8 0.8 1 1"/>
              <geom type="mesh" mesh="hex_link" rgba="0.8 0.8 0.9 0.3" scale="0.01875 0.03635 0.03635"/>
              <site name="s_left_3"  pos="0 0.01817 0" size="0.002" rgba="0 0 1 1"/>
              <site name="s_right_3" pos="0 -0.01817 0" size="0.002" rgba="1 0 0 1"/>
              <body name="link_4" pos="0.01875 0 0">
                <joint name="joint_4" type="hinge" axis="0 1 0"/>
                <geom type="capsule" fromto="-0.00937 0 0 0.00937 0 0" size="0.01757" rgba="0.8 0.8 1 1"/>
                <geom type="mesh" mesh="hex_link" rgba="0.8 0.8 0.9 0.3" scale="0.01875 0.03513 0.03513"/>
                <site name="s_left_4"  pos="0 0.01757 0" size="0.002" rgba="0 0 1 1"/>
                <site name="s_right_4" pos="0 -0.01757 0" size="0.002" rgba="1 0 0 1"/>
                <body name="link_5" pos="0.01875 0 0">
                  <joint name="joint_5" type="hinge" axis="0 1 0"/>
                  <geom type="capsule" fromto="-0.00937 0 0 0.00937 0 0" size="0.01696" rgba="0.8 0.8 1 1"/>
                  <geom type="mesh" mesh="hex_link" rgba="0.8 0.8 0.9 0.3" scale="0.01875 0.03391 0.03391"/>
                  <site name="s_left_5"  pos="0 0.01696 0" size="0.002" rgba="0 0 1 1"/>
                  <site name="s_right_5" pos="0 -0.01696 0" size="0.002" rgba="1 0 0 1"/>
                  <body name="link_6" pos="0.01875 0 0">
                    <joint name="joint_6" type="hinge" axis="0 1 0"/>
                    <geom type="capsule" fromto="-0.00937 0 0 0.00937 0 0" size="0.01635" rgba="0.8 0.8 1 1"/>
                    <geom type="mesh" mesh="hex_link" rgba="0.8 0.8 0.9 0.3" scale="0.01875 0.03270 0.03270"/>
                    <site name="s_left_6"  pos="0 0.01635 0" size="0.002" rgba="0 0 1 1"/>
                    <site name="s_right_6" pos="0 -0.01635 0" size="0.002" rgba="1 0 0 1"/>
                    <body name="link_7" pos="0.01875 0 0">
                      <joint name="joint_7" type="hinge" axis="0 1 0"/>
                      <geom type="capsule" fromto="-0.00937 0 0 0.00937 0 0" size="0.01574" rgba="0.8 0.8 1 1"/>
                      <geom type="mesh" mesh="hex_link" rgba="0.8 0.8 0.9 0.3" scale="0.01875 0.03148 0.03148"/>
                      <site name="s_left_7"  pos="0 0.01574 0" size="0.002" rgba="0 0 1 1"/>
                      <site name="s_right_7" pos="0 -0.01574 0" size="0.002" rgba="1 0 0 1"/>
                      <body name="link_8" pos="0.01875 0 0">
                        <joint name="joint_8" type="hinge" axis="0 1 0"/>
                        <geom type="capsule" fromto="-0.00937 0 0 0.00937 0 0" size="0.01513" rgba="0.8 0.8 1 1"/>
                        <geom type="mesh" mesh="hex_link" rgba="0.8 0.8 0.9 0.3" scale="0.01875 0.03026 0.03026"/>
                        <site name="s_left_8"  pos="0 0.01513 0" size="0.002" rgba="0 0 1 1"/>
                        <site name="s_right_8" pos="0 -0.01513 0" size="0.002" rgba="1 0 0 1"/>
                        <body name="link_9" pos="0.01875 0 0">
                          <joint name="joint_9" type="hinge" axis="0 1 0"/>
                          <geom type="capsule" fromto="-0.00937 0 0 0.00937 0 0" size="0.01452" rgba="0.8 0.8 1 1"/>
                          <geom type="mesh" mesh="hex_link" rgba="0.8 0.8 0.9 0.3" scale="0.01875 0.02904 0.02904"/>
                          <site name="s_left_9"  pos="0 0.01452 0" size="0.002" rgba="0 0 1 1"/>
                          <site name="s_right_9" pos="0 -0.01452 0" size="0.002" rgba="1 0 0 1"/>
                          <body name="link_10" pos="0.01875 0 0">
                            <joint name="joint_10" type="hinge" axis="0 1 0"/>
                            <geom type="capsule" fromto="-0.00937 0 0 0.00937 0 0" size="0.01391" rgba="0.8 0.8 1 1"/>
                            <geom type="mesh" mesh="hex_link" rgba="0.8 0.8 0.9 0.3" scale="0.01875 0.02783 0.02783"/>
                            <site name="s_left_10"  pos="0 0.01391 0" size="0.002" rgba="0 0 1 1"/>
                            <site name="s_right_10" pos="0 -0.01391 0" size="0.002" rgba="1 0 0 1"/>
                            <body name="link_11" pos="0.01875 0 0">
                              <joint name="joint_11" type="hinge" axis="0 1 0"/>
                              <geom type="capsule" fromto="-0.00937 0 0 0.00937 0 0" size="0.01330" rgba="0.8 0.8 1 1"/>
                              <geom type="mesh" mesh="hex_link" rgba="0.8 0.8 0.9 0.3" scale="0.01875 0.02661 0.02661"/>
                              <site name="s_left_11"  pos="0 0.01330 0" size="0.002" rgba="0 0 1 1"/>
                              <site name="s_right_11" pos="0 -0.01330 0" size="0.002" rgba="1 0 0 1"/>
                              <body name="link_12" pos="0.01875 0 0">
                                <joint name="joint_12" type="hinge" axis="0 1 0"/>
                                <geom type="capsule" fromto="-0.00937 0 0 0.00937 0 0" size="0.01270" rgba="0.8 0.8 1 1"/>
                                <geom type="mesh" mesh="hex_link" rgba="0.8 0.8 0.9 0.3" scale="0.01875 0.02539 0.02539"/>
                                <site name="s_left_12"  pos="0 0.01270 0" size="0.002" rgba="0 0 1 1"/>
                                <site name="s_right_12" pos="0 -0.01270 0" size="0.002" rgba="1 0 0 1"/>
                                <body name="link_13" pos="0.01875 0 0">
                                  <joint name="joint_13" type="hinge" axis="0 1 0"/>
                                  <geom type="capsule" fromto="-0.00937 0 0 0.00937 0 0" size="0.01209" rgba="0.8 0.8 1 1"/>
                                  <geom type="mesh" mesh="hex_link" rgba="0.8 0.8 0.9 0.3" scale="0.01875 0.02417 0.02417"/>
                                  <site name="s_left_13"  pos="0 0.01209 0" size="0.002" rgba="0 0 1 1"/>
                                  <site name="s_right_13" pos="0 -0.01209 0" size="0.002" rgba="1 0 0 1"/>
                                  <body name="link_14" pos="0.01875 0 0">
                                    <joint name="joint_14" type="hinge" axis="0 1 0"/>
                                    <geom type="capsule" fromto="-0.00937 0 0 0.00937 0 0" size="0.01148" rgba="0.8 0.8 1 1"/>
                                    <geom type="mesh" mesh="hex_link" rgba="0.8 0.8 0.9 0.3" scale="0.01875 0.02296 0.02296"/>
                                    <site name="s_left_14"  pos="0 0.01148 0" size="0.002" rgba="0 0 1 1"/>
                                    <site name="s_right_14" pos="0 -0.01148 0" size="0.002" rgba="1 0 0 1"/>
                                    <body name="link_15" pos="0.01875 0 0">
                                      <joint name="joint_15" type="hinge" axis="0 1 0"/>
                                      <geom type="capsule" fromto="-0.00937 0 0 0.00937 0 0" size="0.01087" rgba="0.8 0.8 1 1"/>
                                      <geom type="mesh" mesh="hex_link" rgba="0.8 0.8 0.9 0.3" scale="0.01875 0.02174 0.02174"/>
                                      <site name="s_left_15"  pos="0 0.01087 0" size="0.002" rgba="0 0 1 1"/>
                                      <site name="s_right_15" pos="0 -0.01087 0" size="0.002" rgba="1 0 0 1"/>
                                      <body name="link_16" pos="0.01875 0 0">
                                        <joint name="joint_16" type="hinge" axis="0 1 0"/>
                                        <geom type="capsule" fromto="-0.00937 0 0 0.00937 0 0" size="0.01026" rgba="0.8 0.8 1 1"/>
                                        <geom type="mesh" mesh="hex_link" rgba="0.8 0.8 0.9 0.3" scale="0.01875 0.02052 0.02052"/>
                                        <site name="s_left_16"  pos="0 0.01026 0" size="0.002" rgba="0 0 1 1"/>
                                        <site name="s_right_16" pos="0 -0.01026 0" size="0.002" rgba="1 0 0 1"/>
                                        <body name="link_17" pos="0.01875 0 0">
                                          <joint name="joint_17" type="hinge" axis="0 1 0"/>
                                          <geom type="capsule" fromto="-0.00937 0 0 0.00937 0 0" size="0.00965" rgba="0.8 0.8 1 1"/>
                                          <geom type="mesh" mesh="hex_link" rgba="0.8 0.8 0.9 0.3" scale="0.01875 0.01930 0.01930"/>
                                          <site name="s_left_17"  pos="0 0.00965 0" size="0.002" rgba="0 0 1 1"/>
                                          <site name="s_right_17" pos="0 -0.00965 0" size="0.002" rgba="1 0 0 1"/>
                                          <body name="link_18" pos="0.01875 0 0">
                                            <joint name="joint_18" type="hinge" axis="0 1 0"/>
                                            <geom type="capsule" fromto="-0.00937 0 0 0.00937 0 0" size="0.00904" rgba="0.8 0.8 1 1"/>
                                            <geom type="mesh" mesh="hex_link" rgba="0.8 0.8 0.9 0.3" scale="0.01875 0.01809 0.01809"/>
                                            <site name="s_left_18"  pos="0 0.00904 0" size="0.002" rgba="0 0 1 1"/>
                                            <site name="s_right_18" pos="0 -0.00904 0" size="0.002" rgba="1 0 0 1"/>
                                            <body name="link_19" pos="0.01875 0 0">
                                              <joint name="joint_19" type="hinge" axis="0 1 0"/>
                                              <geom type="capsule" fromto="-0.00937 0 0 0.00937 0 0" size="0.00843" rgba="0.8 0.8 1 1"/>
                                              <geom type="mesh" mesh="hex_link" rgba="0.8 0.8 0.9 0.3" scale="0.01875 0.01687 0.01687"/>
                                              <site name="s_left_19"  pos="0 0.00843 0" size="0.002" rgba="0 0 1 1"/>
                                              <site name="s_right_19" pos="0 -0.00843 0" size="0.002" rgba="1 0 0 1"/>
                                              <body name="link_20" pos="0.01875 0 0">
                                                <joint name="joint_20" type="hinge" axis="0 1 0"/>
                                                <geom type="capsule" fromto="-0.00937 0 0 0.00937 0 0" size="0.00783" rgba="0.8 0.8 1 1"/>
                                                <geom type="mesh" mesh="hex_link" rgba="0.8 0.8 0.9 0.3" scale="0.01875 0.01565 0.01565"/>
                                                <site name="s_left_20"  pos="0 0.00783 0" size="0.002" rgba="0 0 1 1"/>
                                                <site name="s_right_20" pos="0 -0.00783 0" size="0.002" rgba="1 0 0 1"/>
                                                <body name="link_21" pos="0.01875 0 0">
                                                  <joint name="joint_21" type="hinge" axis="0 1 0"/>
                                                  <geom type="capsule" fromto="-0.00937 0 0 0.00937 0 0" size="0.00722" rgba="0.8 0.8 1 1"/>
                                                  <geom type="mesh" mesh="hex_link" rgba="0.8 0.8 0.9 0.3" scale="0.01875 0.01443 0.01443"/>
                                                  <site name="s_left_21"  pos="0 0.00722 0" size="0.002" rgba="0 0 1 1"/>
                                                  <site name="s_right_21" pos="0 -0.00722 0" size="0.002" rgba="1 0 0 1"/>
                                                  <body name="link_22" pos="0.01875 0 0">
                                                    <joint name="joint_22" type="hinge" axis="0 1 0"/>
                                                    <geom type="capsule" fromto="-0.00937 0 0 0.00937 0 0" size="0.00661" rgba="0.8 0.8 1 1"/>
                                                    <geom type="mesh" mesh="hex_link" rgba="0.8 0.8 0.9 0.3" scale="0.01875 0.01322 0.01322"/>
                                                    <site name="s_left_22"  pos="0 0.00661 0" size="0.002" rgba="0 0 1 1"/>
                                                    <site name="s_right_22" pos="0 -0.00661 0" size="0.002" rgba="1 0 0 1"/>
                                                    <body name="link_23" pos="0.01875 0 0">
                                                      <joint name="joint_23" type="hinge" axis="0 1 0"/>
                                                      <geom type="capsule" fromto="-0.00937 0 0 0.00937 0 0" size="0.00600" rgba="0.8 0.8 1 1"/>
                                                      <geom type="mesh" mesh="hex_link" rgba="0.8 0.8 0.9 0.3" scale="0.01875 0.01200 0.01200"/>
                                                      <site name="s_left_23"  pos="0 0.00600 0" size="0.002" rgba="0 0 1 1"/>
                                                      <site name="s_right_23" pos="0 -0.00600 0" size="0.002" rgba="1 0 0 1"/>
                                                    </body>
                                                  </body>
                                                </body>
                                              </body>
                                            </body>
                                          </body>
                                        </body>
                                      </body>
                                    </body>
                                  </body>
                                </body>
                              </body>
                            </body>
                          </body>
                        </body>
                      </body>
                    </body>
                  </body>
                </body>
              </body>
            </body>
          </body>
        </body>
      </body>
    </body>  <!-- base -->
    <body name="obj_sphere_hi" pos="0.25 0 0.06">
      <freejoint name="obj_sphere_hi_free"/>
      <geom name="obj_sphere_hi_geom" type="sphere" size="0.025" density="500" rgba="1 0.6 0.2 1"/>
    </body>
  </worldbody>
  <tendon>
    <spatial name="tendon_left">
      <site site="s_left_0"/>
      <site site="s_left_1"/>
      <site site="s_left_2"/>
      <site site="s_left_3"/>
      <site site="s_left_4"/>
      <site site="s_left_5"/>
      <site site="s_left_6"/>
      <site site="s_left_7"/>
      <site site="s_left_8"/>
      <site site="s_left_9"/>
      <site site="s_left_10"/>
      <site site="s_left_11"/>
      <site site="s_left_12"/>
      <site site="s_left_13"/>
      <site site="s_left_14"/>
      <site site="s_left_15"/>
      <site site="s_left_16"/>
      <site site="s_left_17"/>
      <site site="s_left_18"/>
      <site site="s_left_19"/>
      <site site="s_left_20"/>
      <site site="s_left_21"/>
      <site site="s_left_22"/>
      <site site="s_left_23"/>
    </spatial>
    <spatial name="tendon_right">
      <site site="s_right_0"/>
      <site site="s_right_1"/>
      <site site="s_right_2"/>
      <site site="s_right_3"/>
      <site site="s_right_4"/>
      <site site="s_right_5"/>
      <site site="s_right_6"/>
      <site site="s_right_7"/>
      <site site="s_right_8"/>
      <site site="s_right_9"/>
      <site site="s_right_10"/>
      <site site="s_right_11"/>
      <site site="s_right_12"/>
      <site site="s_right_13"/>
      <site site="s_right_14"/>
      <site site="s_right_15"/>
      <site site="s_right_16"/>
      <site site="s_right_17"/>
      <site site="s_right_18"/>
      <site site="s_right_19"/>
      <site site="s_right_20"/>
      <site site="s_right_21"/>
      <site site="s_right_22"/>
      <site site="s_right_23"/>
    </spatial>
  </tendon>
  <actuator>
    <motor name="motor_left"  tendon="tendon_left"  gear="40"/>
    <motor name="motor_right" tendon="tendon_right" gear="40"/>
  </actuator>
</mujoco>