<mujoco model="spiral_tentacle_hex_spirob_2c">
  <option timestep="0.00015" gravity="0 0 -9.81" integrator="Euler" iterations="120"/>
  <default>
    <joint damping="0.2500" frictionloss="0.0100" springref="0"/>
    <geom condim="3" friction="0.8 0.1 0.01" solimp="0.9 0.99 0.001 0.5 2" solref="0.002 1" rgba="0.9 0.9 0.9 1"/>
  </default>
  <asset>
    <mesh name="hex_base" file="hex_base.obj"/>
    <mesh name="hex_0" file="hex_base.obj" scale="0.023224 0.030000 0.050000"/>
    <mesh name="hex_1" file="hex_base.obj" scale="0.020697 0.026736 0.050000"/>
    <mesh name="hex_2" file="hex_base.obj" scale="0.018445 0.023827 0.050000"/>
    <mesh name="hex_3" file="hex_base.obj" scale="0.016438 0.021234 0.050000"/>
    <mesh name="hex_4" file="hex_base.obj" scale="0.014650 0.018924 0.050000"/>
    <mesh name="hex_5" file="hex_base.obj" scale="0.013056 0.016865 0.050000"/>
    <mesh name="hex_6" file="hex_base.obj" scale="0.011635 0.015030 0.050000"/>
    <mesh name="hex_7" file="hex_base.obj" scale="0.010369 0.013395 0.050000"/>
    <mesh name="hex_8" file="hex_base.obj" scale="0.009241 0.011937 0.050000"/>
    <mesh name="hex_9" file="hex_base.obj" scale="0.008236 0.010638 0.050000"/>
    <mesh name="hex_10" file="hex_base.obj" scale="0.007340 0.009481 0.050000"/>
    <mesh name="hex_11" file="hex_base.obj" scale="0.006541 0.008449 0.050000"/>
    <mesh name="hex_12" file="hex_base.obj" scale="0.005829 0.007530 0.050000"/>
    <mesh name="hex_13" file="hex_base.obj" scale="0.005195 0.006711 0.050000"/>
    <mesh name="hex_14" file="hex_base.obj" scale="0.004630 0.005981 0.050000"/>
    <mesh name="hex_15" file="hex_base.obj" scale="0.004126 0.005330 0.050000"/>
    <mesh name="hex_16" file="hex_base.obj" scale="0.003677 0.004750 0.050000"/>
    <mesh name="hex_17" file="hex_base.obj" scale="0.003277 0.004233 0.050000"/>
    <mesh name="hex_18" file="hex_base.obj" scale="0.002920 0.003773 0.050000"/>
    <mesh name="hex_19" file="hex_base.obj" scale="0.002603 0.003362 0.050000"/>
    <mesh name="hex_20" file="hex_base.obj" scale="0.002320 0.002996 0.050000"/>
    <mesh name="hex_21" file="hex_base.obj" scale="0.002067 0.002670 0.050000"/>
    <mesh name="hex_22" file="hex_base.obj" scale="0.001842 0.002380 0.050000"/>
    <mesh name="hex_23" file="hex_base.obj" scale="0.001642 0.002121 0.050000"/>
  </asset>
  <worldbody>
    <geom name="floor" type="plane" pos="0 0 0" size="5 5 0.1" rgba="0.8 0.8 0.8 1"/>
    <body name="base" pos="-0.031831 0.000000 0.025000">
      <geom type="sphere" size="0.015" rgba="0.3 0.3 0.3 1"/>
      <site name="tendon_left_base"  pos="0 0.015000 0" size="0.002"/>
      <site name="tendon_right_base" pos="0 -0.015000 0" size="0.002"/>
      <body name="link_0" pos="0 0 0">
        <joint name="joint_0" type="hinge" axis="0 0 1" pos="0 0 0" range="-45.0 45.0" stiffness="6.000"/>
        <geom name="link_geom_0" type="mesh" mesh="hex_0" pos="0 0 0" density="300.0" margin="0.003"/>
        <site name="tendon_left_0"  pos="0.011612 0.010500 0" size="0.002"/>
        <site name="tendon_right_0" pos="0.011612 -0.010500 0" size="0.002"/>
        <body name="link_1" pos="0.023224 0 0">
          <joint name="joint_1" type="hinge" axis="0 0 1" pos="0 0 0" range="-56.1 56.1" stiffness="5.903"/>
          <geom name="link_geom_1" type="mesh" mesh="hex_1" pos="0 0 0" density="300.0" margin="0.003"/>
          <site name="tendon_left_1"  pos="0.010349 0.009532 0" size="0.002"/>
          <site name="tendon_right_1" pos="0.010349 -0.009532 0" size="0.002"/>
          <body name="link_2" pos="0.020697 0 0">
            <joint name="joint_2" type="hinge" axis="0 0 1" pos="0 0 0" range="-67.2 67.2" stiffness="5.731"/>
            <geom name="link_geom_2" type="mesh" mesh="hex_2" pos="0 0 0" density="300.0" margin="0.003"/>
            <site name="tendon_left_2"  pos="0.009223 0.008650 0" size="0.002"/>
            <site name="tendon_right_2" pos="0.009223 -0.008650 0" size="0.002"/>
            <body name="link_3" pos="0.018445 0 0">
              <joint name="joint_3" type="hinge" axis="0 0 1" pos="0 0 0" range="-78.3 78.3" stiffness="5.514"/>
              <geom name="link_geom_3" type="mesh" mesh="hex_3" pos="0 0 0" density="300.0" margin="0.003"/>
              <site name="tendon_left_3"  pos="0.008219 0.007847 0" size="0.002"/>
              <site name="tendon_right_3" pos="0.008219 -0.007847 0" size="0.002"/>
              <body name="link_4" pos="0.016438 0 0">
                <joint name="joint_4" type="hinge" axis="0 0 1" pos="0 0 0" range="-89.3 89.3" stiffness="5.269"/>
                <geom name="link_geom_4" type="mesh" mesh="hex_4" pos="0 0 0" density="300.0" margin="0.003"/>
                <site name="tendon_left_4"  pos="0.007325 0.007117 0" size="0.002"/>
                <site name="tendon_right_4" pos="0.007325 -0.007117 0" size="0.002"/>
                <body name="link_5" pos="0.014650 0 0">
                  <joint name="joint_5" type="hinge" axis="0 0 1" pos="0 0 0" range="-100.4 100.4" stiffness="5.004"/>
                  <geom name="link_geom_5" type="mesh" mesh="hex_5" pos="0 0 0" density="300.0" margin="0.003"/>
                  <site name="tendon_left_5"  pos="0.006528 0.006453 0" size="0.002"/>
                  <site name="tendon_right_5" pos="0.006528 -0.006453 0" size="0.002"/>
                  <body name="link_6" pos="0.013056 0 0">
                    <joint name="joint_6" type="hinge" axis="0 0 1" pos="0 0 0" range="-111.5 111.5" stiffness="4.726"/>
                    <geom name="link_geom_6" type="mesh" mesh="hex_6" pos="0 0 0" density="300.0" margin="0.003"/>
                    <site name="tendon_left_6"  pos="0.005818 0.005849 0" size="0.002"/>
                    <site name="tendon_right_6" pos="0.005818 -0.005849 0" size="0.002"/>
                    <body name="link_7" pos="0.011635 0 0">
                      <joint name="joint_7" type="hinge" axis="0 0 1" pos="0 0 0" range="-122.6 122.6" stiffness="4.441"/>
                      <geom name="link_geom_7" type="mesh" mesh="hex_7" pos="0 0 0" density="300.0" margin="0.003"/>
                      <site name="tendon_left_7"  pos="0.005185 0.005300 0" size="0.002"/>
                      <site name="tendon_right_7" pos="0.005185 -0.005300 0" size="0.002"/>
                      <body name="link_8" pos="0.010369 0 0">
                        <joint name="joint_8" type="hinge" axis="0 0 1" pos="0 0 0" range="-133.7 133.7" stiffness="4.155"/>
                        <geom name="link_geom_8" type="mesh" mesh="hex_8" pos="0 0 0" density="300.0" margin="0.003"/>
                        <site name="tendon_left_8"  pos="0.004621 0.004801 0" size="0.002"/>
                        <site name="tendon_right_8" pos="0.004621 -0.004801 0" size="0.002"/>
                        <body name="link_9" pos="0.009241 0 0">
                          <joint name="joint_9" type="hinge" axis="0 0 1" pos="0 0 0" range="-144.8 144.8" stiffness="3.870"/>
                          <geom name="link_geom_9" type="mesh" mesh="hex_9" pos="0 0 0" density="300.0" margin="0.003"/>
                          <site name="tendon_left_9"  pos="0.004118 0.004348 0" size="0.002"/>
                          <site name="tendon_right_9" pos="0.004118 -0.004348 0" size="0.002"/>
                          <body name="link_10" pos="0.008236 0 0">
                            <joint name="joint_10" type="hinge" axis="0 0 1" pos="0 0 0" range="-155.9 155.9" stiffness="3.590"/>
                            <geom name="link_geom_10" type="mesh" mesh="hex_10" pos="0 0 0" density="300.0" margin="0.003"/>
                            <site name="tendon_left_10"  pos="0.003670 0.003937 0" size="0.002"/>
                            <site name="tendon_right_10" pos="0.003670 -0.003937 0" size="0.002"/>
                            <body name="link_11" pos="0.007340 0 0">
                              <joint name="joint_11" type="hinge" axis="0 0 1" pos="0 0 0" range="-167.0 167.0" stiffness="3.317"/>
                              <geom name="link_geom_11" type="mesh" mesh="hex_11" pos="0 0 0" density="300.0" margin="0.003"/>
                              <site name="tendon_left_11"  pos="0.003270 0.003563 0" size="0.002"/>
                              <site name="tendon_right_11" pos="0.003270 -0.003563 0" size="0.002"/>
                              <body name="link_12" pos="0.006541 0 0">
                                <joint name="joint_12" type="hinge" axis="0 0 1" pos="0 0 0" range="-178.0 178.0" stiffness="3.054"/>
                                <geom name="link_geom_12" type="mesh" mesh="hex_12" pos="0 0 0" density="300.0" margin="0.003"/>
                                <site name="tendon_left_12"  pos="0.002915 0.003225 0" size="0.002"/>
                                <site name="tendon_right_12" pos="0.002915 -0.003225 0" size="0.002"/>
                                <body name="link_13" pos="0.005829 0 0">
                                  <joint name="joint_13" type="hinge" axis="0 0 1" pos="0 0 0" range="-189.1 189.1" stiffness="2.802"/>
                                  <geom name="link_geom_13" type="mesh" mesh="hex_13" pos="0 0 0" density="300.0" margin="0.003"/>
                                  <site name="tendon_left_13"  pos="0.002598 0.002918 0" size="0.002"/>
                                  <site name="tendon_right_13" pos="0.002598 -0.002918 0" size="0.002"/>
                                  <body name="link_14" pos="0.005195 0 0">
                                    <joint name="joint_14" type="hinge" axis="0 0 1" pos="0 0 0" range="-200.2 200.2" stiffness="2.562"/>
                                    <geom name="link_geom_14" type="mesh" mesh="hex_14" pos="0 0 0" density="300.0" margin="0.003"/>
                                    <site name="tendon_left_14"  pos="0.002315 0.002639 0" size="0.002"/>
                                    <site name="tendon_right_14" pos="0.002315 -0.002639 0" size="0.002"/>
                                    <body name="link_15" pos="0.004630 0 0">
                                      <joint name="joint_15" type="hinge" axis="0 0 1" pos="0 0 0" range="-211.3 211.3" stiffness="2.335"/>
                                      <geom name="link_geom_15" type="mesh" mesh="hex_15" pos="0 0 0" density="300.0" margin="0.003"/>
                                      <site name="tendon_left_15"  pos="0.002063 0.002387 0" size="0.002"/>
                                      <site name="tendon_right_15" pos="0.002063 -0.002387 0" size="0.002"/>
                                      <body name="link_16" pos="0.004126 0 0">
                                        <joint name="joint_16" type="hinge" axis="0 0 1" pos="0 0 0" range="-222.4 222.4" stiffness="2.122"/>
                                        <geom name="link_geom_16" type="mesh" mesh="hex_16" pos="0 0 0" density="300.0" margin="0.003"/>
                                        <site name="tendon_left_16"  pos="0.001839 0.002158 0" size="0.002"/>
                                        <site name="tendon_right_16" pos="0.001839 -0.002158 0" size="0.002"/>
                                        <body name="link_17" pos="0.003677 0 0">
                                          <joint name="joint_17" type="hinge" axis="0 0 1" pos="0 0 0" range="-233.5 233.5" stiffness="1.922"/>
                                          <geom name="link_geom_17" type="mesh" mesh="hex_17" pos="0 0 0" density="300.0" margin="0.003"/>
                                          <site name="tendon_left_17"  pos="0.001639 0.001951 0" size="0.002"/>
                                          <site name="tendon_right_17" pos="0.001639 -0.001951 0" size="0.002"/>
                                          <body name="link_18" pos="0.003277 0 0">
                                            <joint name="joint_18" type="hinge" axis="0 0 1" pos="0 0 0" range="-244.6 244.6" stiffness="1.735"/>
                                            <geom name="link_geom_18" type="mesh" mesh="hex_18" pos="0 0 0" density="300.0" margin="0.003"/>
                                            <site name="tendon_left_18"  pos="0.001460 0.001763 0" size="0.002"/>
                                            <site name="tendon_right_18" pos="0.001460 -0.001763 0" size="0.002"/>
                                            <body name="link_19" pos="0.002920 0 0">
                                              <joint name="joint_19" type="hinge" axis="0 0 1" pos="0 0 0" range="-255.7 255.7" stiffness="1.563"/>
                                              <geom name="link_geom_19" type="mesh" mesh="hex_19" pos="0 0 0" density="300.0" margin="0.003"/>
                                              <site name="tendon_left_19"  pos="0.001301 0.001593 0" size="0.002"/>
                                              <site name="tendon_right_19" pos="0.001301 -0.001593 0" size="0.002"/>
                                              <body name="link_20" pos="0.002603 0 0">
                                                <joint name="joint_20" type="hinge" axis="0 0 1" pos="0 0 0" range="-266.7 266.7" stiffness="1.403"/>
                                                <geom name="link_geom_20" type="mesh" mesh="hex_20" pos="0 0 0" density="300.0" margin="0.003"/>
                                                <site name="tendon_left_20"  pos="0.001160 0.001440 0" size="0.002"/>
                                                <site name="tendon_right_20" pos="0.001160 -0.001440 0" size="0.002"/>
                                                <body name="link_21" pos="0.002320 0 0">
                                                  <joint name="joint_21" type="hinge" axis="0 0 1" pos="0 0 0" range="-277.8 277.8" stiffness="1.257"/>
                                                  <geom name="link_geom_21" type="mesh" mesh="hex_21" pos="0 0 0" density="300.0" margin="0.003"/>
                                                  <site name="tendon_left_21"  pos="0.001034 0.001300 0" size="0.002"/>
                                                  <site name="tendon_right_21" pos="0.001034 -0.001300 0" size="0.002"/>
                                                  <body name="link_22" pos="0.002067 0 0">
                                                    <joint name="joint_22" type="hinge" axis="0 0 1" pos="0 0 0" range="-288.9 288.9" stiffness="1.123"/>
                                                    <geom name="link_geom_22" type="mesh" mesh="hex_22" pos="0 0 0" density="300.0" margin="0.003"/>
                                                    <site name="tendon_left_22"  pos="0.000921 0.001174 0" size="0.002"/>
                                                    <site name="tendon_right_22" pos="0.000921 -0.001174 0" size="0.002"/>
                                                    <body name="link_23" pos="0.001842 0 0">
                                                      <joint name="joint_23" type="hinge" axis="0 0 1" pos="0 0 0" range="-300.0 300.0" stiffness="1.000"/>
                                                      <geom name="link_geom_23" type="mesh" mesh="hex_23" pos="0 0 0" density="300.0" margin="0.003"/>
                                                      <site name="tendon_left_23"  pos="0.000821 0.001060 0" size="0.002"/>
                                                      <site name="tendon_right_23" pos="0.000821 -0.001060 0" size="0.002"/>
                                                    </body>
                                                  </body>
                                                </body>
                                              </body>
                                            </body>
                                          </body>
                                        </body>
                                      </body>
                                    </body>
                                  </body>
                                </body>
                              </body>
                            </body>
                          </body>
                        </body>
                      </body>
                    </body>
                  </body>
                </body>
              </body>
            </body>
          </body>
        </body>
      </body>
    </body>  <!-- base -->
    <body name="obj_sphere" pos="0.128169 0.042900 0.018000">
      <joint name="obj_sphere_free" type="free"/>
      <geom name="obj_sphere_col" type="sphere" size="0.018000" density="2000" friction="1.0 0.4 0.03" margin="0.004" rgba="0 0 0 0"/>
      <geom name="obj_sphere_vis" type="sphere" size="0.010000" contype="0" conaffinity="0" rgba="0 1 0 1"/>
    </body>
  </worldbody>
  <tendon>
    <spatial name="tendon_left" limited="false" width="0.002">
      <site site="tendon_left_base"/>
      <site site="tendon_left_0"/>
      <site site="tendon_left_1"/>
      <site site="tendon_left_2"/>
      <site site="tendon_left_3"/>
      <site site="tendon_left_4"/>
      <site site="tendon_left_5"/>
      <site site="tendon_left_6"/>
      <site site="tendon_left_7"/>
      <site site="tendon_left_8"/>
      <site site="tendon_left_9"/>
      <site site="tendon_left_10"/>
      <site site="tendon_left_11"/>
      <site site="tendon_left_12"/>
      <site site="tendon_left_13"/>
      <site site="tendon_left_14"/>
      <site site="tendon_left_15"/>
      <site site="tendon_left_16"/>
      <site site="tendon_left_17"/>
      <site site="tendon_left_18"/>
      <site site="tendon_left_19"/>
      <site site="tendon_left_20"/>
      <site site="tendon_left_21"/>
      <site site="tendon_left_22"/>
      <site site="tendon_left_23"/>
    </spatial>
    <spatial name="tendon_right" limited="false" width="0.002">
      <site site="tendon_right_base"/>
      <site site="tendon_right_0"/>
      <site site="tendon_right_1"/>
      <site site="tendon_right_2"/>
      <site site="tendon_right_3"/>
      <site site="tendon_right_4"/>
      <site site="tendon_right_5"/>
      <site site="tendon_right_6"/>
      <site site="tendon_right_7"/>
      <site site="tendon_right_8"/>
      <site site="tendon_right_9"/>
      <site site="tendon_right_10"/>
      <site site="tendon_right_11"/>
      <site site="tendon_right_12"/>
      <site site="tendon_right_13"/>
      <site site="tendon_right_14"/>
      <site site="tendon_right_15"/>
      <site site="tendon_right_16"/>
      <site site="tendon_right_17"/>
      <site site="tendon_right_18"/>
      <site site="tendon_right_19"/>
      <site site="tendon_right_20"/>
      <site site="tendon_right_21"/>
      <site site="tendon_right_22"/>
      <site site="tendon_right_23"/>
    </spatial>
  </tendon>
  <actuator>
    <motor name="motor_left"  tendon="tendon_left"  gear="5000.000"/>
    <motor name="motor_right" tendon="tendon_right" gear="5000.000"/>
  </actuator>
</mujoco>