<mujoco model="spiral_tentacle_hex">\n  <option timestep="0.002" gravity="0 0 0"/>\n\n  <asset>\n    <mesh name="hex_0" builtin="cone" params="6 1" scale="0.020000 0.020000 0.013393"/>\n    <mesh name="hex_1" builtin="cone" params="6 1" scale="0.019391 0.019391 0.013043"/>\n    <mesh name="hex_2" builtin="cone" params="6 1" scale="0.018783 0.018783 0.012694"/>\n    <mesh name="hex_3" builtin="cone" params="6 1" scale="0.018174 0.018174 0.012345"/>\n    <mesh name="hex_4" builtin="cone" params="6 1" scale="0.017565 0.017565 0.011995"/>\n    <mesh name="hex_5" builtin="cone" params="6 1" scale="0.016957 0.016957 0.011646"/>\n    <mesh name="hex_6" builtin="cone" params="6 1" scale="0.016348 0.016348 0.011297"/>\n    <mesh name="hex_7" builtin="cone" params="6 1" scale="0.015739 0.015739 0.010947"/>\n    <mesh name="hex_8" builtin="cone" params="6 1" scale="0.015130 0.015130 0.010598"/>\n    <mesh name="hex_9" builtin="cone" params="6 1" scale="0.014522 0.014522 0.010248"/>\n    <mesh name="hex_10" builtin="cone" params="6 1" scale="0.013913 0.013913 0.009899"/>\n    <mesh name="hex_11" builtin="cone" params="6 1" scale="0.013304 0.013304 0.009550"/>\n    <mesh name="hex_12" builtin="cone" params="6 1" scale="0.012696 0.012696 0.009200"/>\n    <mesh name="hex_13" builtin="cone" params="6 1" scale="0.012087 0.012087 0.008851"/>\n    <mesh name="hex_14" builtin="cone" params="6 1" scale="0.011478 0.011478 0.008502"/>\n    <mesh name="hex_15" builtin="cone" params="6 1" scale="0.010870 0.010870 0.008152"/>\n    <mesh name="hex_16" builtin="cone" params="6 1" scale="0.010261 0.010261 0.007803"/>\n    <mesh name="hex_17" builtin="cone" params="6 1" scale="0.009652 0.009652 0.007453"/>\n    <mesh name="hex_18" builtin="cone" params="6 1" scale="0.009043 0.009043 0.007104"/>\n    <mesh name="hex_19" builtin="cone" params="6 1" scale="0.008435 0.008435 0.006755"/>\n    <mesh name="hex_20" builtin="cone" params="6 1" scale="0.007826 0.007826 0.006405"/>\n    <mesh name="hex_21" builtin="cone" params="6 1" scale="0.007217 0.007217 0.006056"/>\n    <mesh name="hex_22" builtin="cone" params="6 1" scale="0.006609 0.006609 0.005707"/>\n    <mesh name="hex_23" builtin="cone" params="6 1" scale="0.006000 0.006000 0.005357"/>\n  </asset>\n\n  <worldbody>\n    <body name="base" pos="0 0 0.005000">\n      <body name="link_0" pos="0.026786 0 0">\n        <joint name="joint_0" type="hinge" axis="0 0 1" pos="-0.013393 0 0" range="-120 120" damping="0.05"/>\n        <geom name="geom_0" type="mesh" mesh="hex_0" euler="0 90 30" density="1000" rgba="0.9 0.9 0.9 1"/>\n        <site name="site_left_0" pos="0.013393 0.020000 0" size="0.005000" rgba="1 0 0 1"/>\n        <site name="site_right_0" pos="0.013393 -0.020000 0" size="0.005000" rgba="0 0 1 1"/>\n      <body name="link_1" pos="0.026087 0 0">\n        <joint name="joint_1" type="hinge" axis="0 0 1" pos="-0.013043 0 0" range="-120 120" damping="0.05"/>\n        <geom name="geom_1" type="mesh" mesh="hex_1" euler="0 90 30" density="1000" rgba="0.9 0.9 0.9 1"/>\n        <site name="site_left_1" pos="0.013043 0.019391 0" size="0.004848" rgba="1 0 0 1"/>\n        <site name="site_right_1" pos="0.013043 -0.019391 0" size="0.004848" rgba="0 0 1 1"/>\n      <body name="link_2" pos="0.025388 0 0">\n        <joint name="joint_2" type="hinge" axis="0 0 1" pos="-0.012694 0 0" range="-120 120" damping="0.05"/>\n        <geom name="geom_2" type="mesh" mesh="hex_2" euler="0 90 30" density="1000" rgba="0.9 0.9 0.9 1"/>\n        <site name="site_left_2" pos="0.012694 0.018783 0" size="0.004696" rgba="1 0 0 1"/>\n        <site name="site_right_2" pos="0.012694 -0.018783 0" size="0.004696" rgba="0 0 1 1"/>\n      <body name="link_3" pos="0.024689 0 0">\n        <joint name="joint_3" type="hinge" axis="0 0 1" pos="-0.012345 0 0" range="-120 120" damping="0.05"/>\n        <geom name="geom_3" type="mesh" mesh="hex_3" euler="0 90 30" density="1000" rgba="0.9 0.9 0.9 1"/>\n        <site name="site_left_3" pos="0.012345 0.018174 0" size="0.004543" rgba="1 0 0 1"/>\n        <site name="site_right_3" pos="0.012345 -0.018174 0" size="0.004543" rgba="0 0 1 1"/>\n      <body name="link_4" pos="0.023991 0 0">\n        <joint name="joint_4" type="hinge" axis="0 0 1" pos="-0.011995 0 0" range="-120 120" damping="0.05"/>\n        <geom name="geom_4" type="mesh" mesh="hex_4" euler="0 90 30" density="1000" rgba="0.9 0.9 0.9 1"/>\n        <site name="site_left_4" pos="0.011995 0.017565 0" size="0.004391" rgba="1 0 0 1"/>\n        <site name="site_right_4" pos="0.011995 -0.017565 0" size="0.004391" rgba="0 0 1 1"/>\n      <body name="link_5" pos="0.023292 0 0">\n        <joint name="joint_5" type="hinge" axis="0 0 1" pos="-0.011646 0 0" range="-120 120" damping="0.05"/>\n        <geom name="geom_5" type="mesh" mesh="hex_5" euler="0 90 30" density="1000" rgba="0.9 0.9 0.9 1"/>\n        <site name="site_left_5" pos="0.011646 0.016957 0" size="0.004239" rgba="1 0 0 1"/>\n        <site name="site_right_5" pos="0.011646 -0.016957 0" size="0.004239" rgba="0 0 1 1"/>\n      <body name="link_6" pos="0.022593 0 0">\n        <joint name="joint_6" type="hinge" axis="0 0 1" pos="-0.011297 0 0" range="-120 120" damping="0.05"/>\n        <geom name="geom_6" type="mesh" mesh="hex_6" euler="0 90 30" density="1000" rgba="0.9 0.9 0.9 1"/>\n        <site name="site_left_6" pos="0.011297 0.016348 0" size="0.004087" rgba="1 0 0 1"/>\n        <site name="site_right_6" pos="0.011297 -0.016348 0" size="0.004087" rgba="0 0 1 1"/>\n      <body name="link_7" pos="0.021894 0 0">\n        <joint name="joint_7" type="hinge" axis="0 0 1" pos="-0.010947 0 0" range="-120 120" damping="0.05"/>\n        <geom name="geom_7" type="mesh" mesh="hex_7" euler="0 90 30" density="1000" rgba="0.9 0.9 0.9 1"/>\n        <site name="site_left_7" pos="0.010947 0.015739 0" size="0.003935" rgba="1 0 0 1"/>\n        <site name="site_right_7" pos="0.010947 -0.015739 0" size="0.003935" rgba="0 0 1 1"/>\n      <body name="link_8" pos="0.021196 0 0">\n        <joint name="joint_8" type="hinge" axis="0 0 1" pos="-0.010598 0 0" range="-120 120" damping="0.05"/>\n        <geom name="geom_8" type="mesh" mesh="hex_8" euler="0 90 30" density="1000" rgba="0.9 0.9 0.9 1"/>\n        <site name="site_left_8" pos="0.010598 0.015130 0" size="0.003783" rgba="1 0 0 1"/>\n        <site name="site_right_8" pos="0.010598 -0.015130 0" size="0.003783" rgba="0 0 1 1"/>\n      <body name="link_9" pos="0.020497 0 0">\n        <joint name="joint_9" type="hinge" axis="0 0 1" pos="-0.010248 0 0" range="-120 120" damping="0.05"/>\n        <geom name="geom_9" type="mesh" mesh="hex_9" euler="0 90 30" density="1000" rgba="0.9 0.9 0.9 1"/>\n        <site name="site_left_9" pos="0.010248 0.014522 0" size="0.003630" rgba="1 0 0 1"/>\n        <site name="site_right_9" pos="0.010248 -0.014522 0" size="0.003630" rgba="0 0 1 1"/>\n      <body name="link_10" pos="0.019798 0 0">\n        <joint name="joint_10" type="hinge" axis="0 0 1" pos="-0.009899 0 0" range="-120 120" damping="0.05"/>\n        <geom name="geom_10" type="mesh" mesh="hex_10" euler="0 90 30" density="1000" rgba="0.9 0.9 0.9 1"/>\n        <site name="site_left_10" pos="0.009899 0.013913 0" size="0.003478" rgba="1 0 0 1"/>\n        <site name="site_right_10" pos="0.009899 -0.013913 0" size="0.003478" rgba="0 0 1 1"/>\n      <body name="link_11" pos="0.019099 0 0">\n        <joint name="joint_11" type="hinge" axis="0 0 1" pos="-0.009550 0 0" range="-120 120" damping="0.05"/>\n        <geom name="geom_11" type="mesh" mesh="hex_11" euler="0 90 30" density="1000" rgba="0.9 0.9 0.9 1"/>\n        <site name="site_left_11" pos="0.009550 0.013304 0" size="0.003326" rgba="1 0 0 1"/>\n        <site name="site_right_11" pos="0.009550 -0.013304 0" size="0.003326" rgba="0 0 1 1"/>\n      <body name="link_12" pos="0.018401 0 0">\n        <joint name="joint_12" type="hinge" axis="0 0 1" pos="-0.009200 0 0" range="-120 120" damping="0.05"/>\n        <geom name="geom_12" type="mesh" mesh="hex_12" euler="0 90 30" density="1000" rgba="0.9 0.9 0.9 1"/>\n        <site name="site_left_12" pos="0.009200 0.012696 0" size="0.003174" rgba="1 0 0 1"/>\n        <site name="site_right_12" pos="0.009200 -0.012696 0" size="0.003174" rgba="0 0 1 1"/>\n      <body name="link_13" pos="0.017702 0 0">\n        <joint name="joint_13" type="hinge" axis="0 0 1" pos="-0.008851 0 0" range="-120 120" damping="0.05"/>\n        <geom name="geom_13" type="mesh" mesh="hex_13" euler="0 90 30" density="1000" rgba="0.9 0.9 0.9 1"/>\n        <site name="site_left_13" pos="0.008851 0.012087 0" size="0.003022" rgba="1 0 0 1"/>\n        <site name="site_right_13" pos="0.008851 -0.012087 0" size="0.003022" rgba="0 0 1 1"/>\n      <body name="link_14" pos="0.017003 0 0">\n        <joint name="joint_14" type="hinge" axis="0 0 1" pos="-0.008502 0 0" range="-120 120" damping="0.05"/>\n        <geom name="geom_14" type="mesh" mesh="hex_14" euler="0 90 30" density="1000" rgba="0.9 0.9 0.9 1"/>\n        <site name="site_left_14" pos="0.008502 0.011478 0" size="0.002870" rgba="1 0 0 1"/>\n        <site name="site_right_14" pos="0.008502 -0.011478 0" size="0.002870" rgba="0 0 1 1"/>\n      <body name="link_15" pos="0.016304 0 0">\n        <joint name="joint_15" type="hinge" axis="0 0 1" pos="-0.008152 0 0" range="-120 120" damping="0.05"/>\n        <geom name="geom_15" type="mesh" mesh="hex_15" euler="0 90 30" density="1000" rgba="0.9 0.9 0.9 1"/>\n        <site name="site_left_15" pos="0.008152 0.010870 0" size="0.002717" rgba="1 0 0 1"/>\n        <site name="site_right_15" pos="0.008152 -0.010870 0" size="0.002717" rgba="0 0 1 1"/>\n      <body name="link_16" pos="0.015606 0 0">\n        <joint name="joint_16" type="hinge" axis="0 0 1" pos="-0.007803 0 0" range="-120 120" damping="0.05"/>\n        <geom name="geom_16" type="mesh" mesh="hex_16" euler="0 90 30" density="1000" rgba="0.9 0.9 0.9 1"/>\n        <site name="site_left_16" pos="0.007803 0.010261 0" size="0.002565" rgba="1 0 0 1"/>\n        <site name="site_right_16" pos="0.007803 -0.010261 0" size="0.002565" rgba="0 0 1 1"/>\n      <body name="link_17" pos="0.014907 0 0">\n        <joint name="joint_17" type="hinge" axis="0 0 1" pos="-0.007453 0 0" range="-120 120" damping="0.05"/>\n        <geom name="geom_17" type="mesh" mesh="hex_17" euler="0 90 30" density="1000" rgba="0.9 0.9 0.9 1"/>\n        <site name="site_left_17" pos="0.007453 0.009652 0" size="0.002413" rgba="1 0 0 1"/>\n        <site name="site_right_17" pos="0.007453 -0.009652 0" size="0.002413" rgba="0 0 1 1"/>\n      <body name="link_18" pos="0.014208 0 0">\n        <joint name="joint_18" type="hinge" axis="0 0 1" pos="-0.007104 0 0" range="-120 120" damping="0.05"/>\n        <geom name="geom_18" type="mesh" mesh="hex_18" euler="0 90 30" density="1000" rgba="0.9 0.9 0.9 1"/>\n        <site name="site_left_18" pos="0.007104 0.009043 0" size="0.002261" rgba="1 0 0 1"/>\n        <site name="site_right_18" pos="0.007104 -0.009043 0" size="0.002261" rgba="0 0 1 1"/>\n      <body name="link_19" pos="0.013509 0 0">\n        <joint name="joint_19" type="hinge" axis="0 0 1" pos="-0.006755 0 0" range="-120 120" damping="0.05"/>\n        <geom name="geom_19" type="mesh" mesh="hex_19" euler="0 90 30" density="1000" rgba="0.9 0.9 0.9 1"/>\n        <site name="site_left_19" pos="0.006755 0.008435 0" size="0.002109" rgba="1 0 0 1"/>\n        <site name="site_right_19" pos="0.006755 -0.008435 0" size="0.002109" rgba="0 0 1 1"/>\n      <body name="link_20" pos="0.012811 0 0">\n        <joint name="joint_20" type="hinge" axis="0 0 1" pos="-0.006405 0 0" range="-120 120" damping="0.05"/>\n        <geom name="geom_20" type="mesh" mesh="hex_20" euler="0 90 30" density="1000" rgba="0.9 0.9 0.9 1"/>\n        <site name="site_left_20" pos="0.006405 0.007826 0" size="0.001957" rgba="1 0 0 1"/>\n        <site name="site_right_20" pos="0.006405 -0.007826 0" size="0.001957" rgba="0 0 1 1"/>\n      <body name="link_21" pos="0.012112 0 0">\n        <joint name="joint_21" type="hinge" axis="0 0 1" pos="-0.006056 0 0" range="-120 120" damping="0.05"/>\n        <geom name="geom_21" type="mesh" mesh="hex_21" euler="0 90 30" density="1000" rgba="0.9 0.9 0.9 1"/>\n        <site name="site_left_21" pos="0.006056 0.007217 0" size="0.001804" rgba="1 0 0 1"/>\n        <site name="site_right_21" pos="0.006056 -0.007217 0" size="0.001804" rgba="0 0 1 1"/>\n      <body name="link_22" pos="0.011413 0 0">\n        <joint name="joint_22" type="hinge" axis="0 0 1" pos="-0.005707 0 0" range="-120 120" damping="0.05"/>\n        <geom name="geom_22" type="mesh" mesh="hex_22" euler="0 90 30" density="1000" rgba="0.9 0.9 0.9 1"/>\n        <site name="site_left_22" pos="0.005707 0.006609 0" size="0.001652" rgba="1 0 0 1"/>\n        <site name="site_right_22" pos="0.005707 -0.006609 0" size="0.001652" rgba="0 0 1 1"/>\n      <body name="link_23" pos="0.010714 0 0">\n        <joint name="joint_23" type="hinge" axis="0 0 1" pos="-0.005357 0 0" range="-120 120" damping="0.05"/>\n        <geom name="geom_23" type="mesh" mesh="hex_23" euler="0 90 30" density="1000" rgba="0.9 0.9 0.9 1"/>\n        <site name="site_left_23" pos="0.005357 0.006000 0" size="0.001500" rgba="1 0 0 1"/>\n        <site name="site_right_23" pos="0.005357 -0.006000 0" size="0.001500" rgba="0 0 1 1"/>\n      </body>\n      </body>\n      </body>\n      </body>\n      </body>\n      </body>\n      </body>\n      </body>\n      </body>\n      </body>\n      </body>\n      </body>\n      </body>\n      </body>\n      </body>\n      </body>\n      </body>\n      </body>\n      </body>\n      </body>\n      </body>\n      </body>\n      </body>\n      </body>\n    </body> <!-- end base -->\n    <geom name="floor" type="plane" size="5 5 0.1" pos="0 0 -1" rgba="0.8 0.8 0.8 1"/>\n    <body name="ball" pos="0.500000 0 0.005000">\n      <joint name="ball_free" type="free"/>\n      <geom name="ball_geom" type="sphere" size="0.014000" density="300" friction="1 0.1 0.01" rgba="0 1 0 1"/>\n    </body>\n  </worldbody>\n\n  <tendon>\n    <spatial name="tendon_left" width="0.001">\n      <site site="site_left_0"/>\n      <site site="site_left_1"/>\n      <site site="site_left_2"/>\n      <site site="site_left_3"/>\n      <site site="site_left_4"/>\n      <site site="site_left_5"/>\n      <site site="site_left_6"/>\n      <site site="site_left_7"/>\n      <site site="site_left_8"/>\n      <site site="site_left_9"/>\n      <site site="site_left_10"/>\n      <site site="site_left_11"/>\n      <site site="site_left_12"/>\n      <site site="site_left_13"/>\n      <site site="site_left_14"/>\n      <site site="site_left_15"/>\n      <site site="site_left_16"/>\n      <site site="site_left_17"/>\n      <site site="site_left_18"/>\n      <site site="site_left_19"/>\n      <site site="site_left_20"/>\n      <site site="site_left_21"/>\n      <site site="site_left_22"/>\n      <site site="site_left_23"/>\n    </spatial>\n    <spatial name="tendon_right" width="0.001">\n      <site site="site_right_0"/>\n      <site site="site_right_1"/>\n      <site site="site_right_2"/>\n      <site site="site_right_3"/>\n      <site site="site_right_4"/>\n      <site site="site_right_5"/>\n      <site site="site_right_6"/>\n      <site site="site_right_7"/>\n      <site site="site_right_8"/>\n      <site site="site_right_9"/>\n      <site site="site_right_10"/>\n      <site site="site_right_11"/>\n      <site site="site_right_12"/>\n      <site site="site_right_13"/>\n      <site site="site_right_14"/>\n      <site site="site_right_15"/>\n      <site site="site_right_16"/>\n      <site site="site_right_17"/>\n      <site site="site_right_18"/>\n      <site site="site_right_19"/>\n      <site site="site_right_20"/>\n      <site site="site_right_21"/>\n      <site site="site_right_22"/>\n      <site site="site_right_23"/>\n    </spatial>\n  </tendon>\n\n  <actuator>\n    <motor name="motor_left" tendon="tendon_left" ctrlrange="-1 1" gear="1"/>\n    <motor name="motor_right" tendon="tendon_right" ctrlrange="-1 1" gear="1"/>\n  </actuator>\n</mujoco>